02/12/2019 17:15:54 program started
02/12/2019 17:15:54 command line: /home/mushalali/bin/srst2 --input_se test1.fq --output test1_srst2 --gene_db ARGannot_r3.fasta
02/12/2019 17:15:54 Total single reads found:1
02/12/2019 17:15:54 Building bowtie2 index for ARGannot_r3.fasta...
02/12/2019 17:15:54 Running: bowtie2-build ARGannot_r3.fasta ARGannot_r3.fasta
Settings:
  Output files: "ARGannot_r3.fasta.*.bt2"
  Line rate: 6 (line is 64 bytes)
  Lines per side: 1 (side is 64 bytes)
  Offset rate: 4 (one in 16)
  FTable chars: 10
  Strings: unpacked
  Max bucket size: default
  Max bucket size, sqrt multiplier: default
  Max bucket size, len divisor: 4
  Difference-cover sample period: 1024
  Endianness: little
  Actual local endianness: little
  Sanity checking: disabled
  Assertions: disabled
  Random seed: 0
  Sizeofs: void*:8, int:4, long:8, size_t:8
Input files DNA, FASTA:
  ARGannot_r3.fasta
Error: could not open ARGannot_r3.fasta
Total time for call to driver() for forward index: 00:00:01
Error: Encountered internal Bowtie 2 exception (#1)
Command: bowtie2-build ARGannot_r3.fasta ARGannot_r3.fasta 
Traceback (most recent call last):
  File "/home/mushalali/bin/srst2", line 11, in <module>
    load_entry_point('srst2==0.2.0', 'console_scripts', 'srst2')()
  File "/home/mushalali/.local/lib/python2.7/site-packages/srst2/srst2.py", line 1727, in main
    bowtie_index(args.gene_db) # index the gene databases
  File "/home/mushalali/.local/lib/python2.7/site-packages/srst2/srst2.py", line 155, in bowtie_index
    run_command([get_bowtie_execs()[1], fasta, fasta])
  File "/home/mushalali/.local/lib/python2.7/site-packages/srst2/srst2.py", line 143, in run_command
    raise CommandError({"message": message})
srst2.srst2.CommandError: {'message': "Command 'bowtie2-build ARGannot_r3.fasta ARGannot_r3.fasta' failed with non-zero exit status: 1"}
